2019.12.24 
    python2.7 - python2: /usr/bin/python2 /usr/bin/python2.7 /usr/bin/python2.7-config /usr/lib/python2.7 /etc/python2.7 /usr/local/lib/python2.7 /usr/include/python2.7 /usr/share/man/man1/python2.1.gz
    python3.7 - python3: /usr/bin/python3.6m /usr/bin/python3 /usr/bin/python3.6m-config /usr/bin/python3.6 /usr/bin/python3.6-config /usr/lib/python3.8 /usr/lib/python3 /usr/lib/python3.7 /usr/lib/python3.6 /etc/python3 /etc/python3.6 /usr/local/lib/python3.6 /usr/include/python3.6m /usr/include/python3.6 /usr/share/python3 /usr/share/man/man1/python3.1.gz
    에서는 pyserial 문제발생하지 않음

========================================================================
Marius Kruger (amanica) wrote on 2015-10-04:

   I updated yesterday and got this issue afterwards.

   I tried the following workaround with worked for me :

   --- serialposix.py.stock 2015-10-03 06:53:45.241261071 -0700
   +++ serialposix.py 2015-10-03 06:55:07.481262475 -0700
   @@ -457,7 +457,11 @@
             # Disconnected devices, at least on Linux, show the
             # behavior that they are always ready to read immediately
             # but reading returns nothing.
   - raise SerialException('device reports readiness to read but returned no data (device disconnected?)')
   + # retrying the read seems to get me past this error:
   + # [ERROR] Can't read from printer (disconnected?) (SerialException): device reports readiness to read but returned no data (device disconnected?)
   +
   + #raise SerialException('device reports readiness to read but returned no data (device disconnected?)')
   + pass

see https://superuser.com/questions/979722/serialport-doenst-work-correctly-after-ubuntu-update#

=========================================================================
gadLinux (gad-aguilardelgado) wrote on 2015-12-29:

   Here they say it's fixed in 3.13.0-66
   https://github.com/pyserial/pyserial/issues/17

